Workbook

Sheet Sales Quantity
A1: =Data!B1 -> MONTH | B1: =Data!C1 -> Region | C1: =Data!D1 -> City | D1: =Data!E1 -> PRD | E1: =Data!F1 -> OPQ (Old plan Quantity) | F1: =Data!G1 -> NPQ(New plan Quantity) | G1: Old Price | H1: New Price | I1: Old Revenue | J1: New Revenue | K1: Old Price per Unit | L1: New Price per Unit | M1: =Data!M2
A2: =Data!B2 -> Month1 | B2: =Data!C2 -> N | C2: =Data!D2 -> Chennai | D2: =Data!E2 -> PowerSip | E2: =Data!F2 -> 21497 | F2: =Data!G2 -> 22572 | G2: =IF(D2="PowerSip", 135, IF(D2="HappyGrow", 60, "")) -> 135 | H2: =IF(D2="PowerSip", 140, IF(D2="HappyGrow", 70, "")) -> 140 | I2: =E2 * G2 -> 2902095 | J2: =F2 * H2 -> 3160080 | K2: =IF(E2=0, "", I2 / E2) -> 135 | L2: =IF(F2=0, "", J2 / F2) -> 140
A3: =Data!B3 -> Month1 | B3: =Data!C3 -> N | C3: =Data!D3 -> Chennai | D3: =Data!E3 -> HappyGrow | E3: =Data!F3 -> 16650 | F3: =Data!G3 -> 16817 | G3: =IF(D3="PowerSip", 135, IF(D3="HappyGrow", 60, "")) -> 60 | H3: =IF(D3="PowerSip", 140, IF(D3="HappyGrow", 70, "")) -> 70 | I3: =E3 * G3 -> 999000 | J3: =F3 * H3 -> 1177190 | K3: =IF(E3=0, "", I3 / E3) -> 60 | L3: =IF(F3=0, "", J3 / F3) -> 70
A4: =Data!B4 -> Month1 | B4: =Data!C4 -> E | C4: =Data!D4 -> Chennai | D4: =Data!E4 -> PowerSip | E4: =Data!F4 -> 11470 | F4: =Data!G4 -> 12044 | G4: =IF(D4="PowerSip", 135, IF(D4="HappyGrow", 60, "")) -> 135 | H4: =IF(D4="PowerSip", 140, IF(D4="HappyGrow", 70, "")) -> 140 | I4: =E4 * G4 -> 1548450 | J4: =F4 * H4 -> 1686160 | K4: =IF(E4=0, "", I4 / E4) -> 135 | L4: =IF(F4=0, "", J4 / F4) -> 140
A5: =Data!B5 -> Month1 | B5: =Data!C5 -> E | C5: =Data!D5 -> Chennai | D5: =Data!E5 -> HappyGrow | E5: =Data!F5 -> 22348 | F5: =Data!G5 -> 22572 | G5: =IF(D5="PowerSip", 135, IF(D5="HappyGrow", 60, "")) -> 60 | H5: =IF(D5="PowerSip", 140, IF(D5="HappyGrow", 70, "")) -> 70 | I5: =E5 * G5 -> 1340880 | J5: =F5 * H5 -> 1580040 | K5: =IF(E5=0, "", I5 / E5) -> 60 | L5: =IF(F5=0, "", J5 / F5) -> 70
A6: =Data!B6 -> Month1 | B6: =Data!C6 -> W | C6: =Data!D6 -> Chennai | D6: =Data!E6 -> PowerSip | E6: =Data!F6 -> 13727 | F6: =Data!G6 -> 14551 | G6: =IF(D6="PowerSip", 135, IF(D6="HappyGrow", 60, "")) -> 135 | H6: =IF(D6="PowerSip", 140, IF(D6="HappyGrow", 70, "")) -> 140 | I6: =E6 * G6 -> 1853145 | J6: =F6 * H6 -> 2037140 | K6: =IF(E6=0, "", I6 / E6) -> 135 | L6: =IF(F6=0, "", J6 / F6) -> 140
A7: =Data!B7 -> Month1 | B7: =Data!C7 -> W | C7: =Data!D7 -> Chennai | D7: =Data!E7 -> HappyGrow | E7: =Data!F7 -> 15799 | F7: =Data!G7 -> 15957 | G7: =IF(D7="PowerSip", 135, IF(D7="HappyGrow", 60, "")) -> 60 | H7: =IF(D7="PowerSip", 140, IF(D7="HappyGrow", 70, "")) -> 70 | I7: =E7 * G7 -> 947940 | J7: =F7 * H7 -> 1116990 | K7: =IF(E7=0, "", I7 / E7) -> 60 | L7: =IF(F7=0, "", J7 / F7) -> 70
A8: =Data!B8 -> Month1 | B8: =Data!C8 -> S | C8: =Data!D8 -> Chennai | D8: =Data!E8 -> PowerSip | E8: =Data!F8 -> 24827 | F8: =Data!G8 -> 26565 | G8: =IF(D8="PowerSip", 135, IF(D8="HappyGrow", 60, "")) -> 135 | H8: =IF(D8="PowerSip", 140, IF(D8="HappyGrow", 70, "")) -> 140 | I8: =E8 * G8 -> 3351645 | J8: =F8 * H8 -> 3719100 | K8: =G8 * I8 -> 452472075 | L8: =IF(F8=0, "", J8 / F8) -> 140
A9: =Data!B9 -> Month1 | B9: =Data!C9 -> S | C9: =Data!D9 -> Chennai | D9: =Data!E9 -> HappyGrow | E9: =Data!F9 -> 13468 | F9: =Data!G9 -> 13603 | G9: =IF(D9="PowerSip", 135, IF(D9="HappyGrow", 60, "")) -> 60 | H9: =IF(D9="PowerSip", 140, IF(D9="HappyGrow", 70, "")) -> 70 | I9: =E9 * G9 -> 808080 | J9: =F9 * H9 -> 952210 | K9: =IF(E9=0, "", I9 / E9) -> 60 | L9: =IF(F9=0, "", J9 / F9) -> 70
A10: =Data!B10 -> Month1 | B10: =Data!C10 -> N | C10: =Data!D10 -> Mumbai | D10: =Data!E10 -> PowerSip | E10: =Data!F10 -> 22237 | F10: =Data!G10 -> 23794 | G10: =IF(D10="PowerSip", 135, IF(D10="HappyGrow", 60, "")) -> 135 | H10: =IF(D10="PowerSip", 140, IF(D10="HappyGrow", 70, "")) -> 140 | I10: =E10 * G10 -> 3001995 | J10: =F10 * H10 -> 3331160 | K10: =IF(E10=0, "", I10 / E10) -> 135 | L10: =IF(F10=0, "", J10 / F10) -> 140
A11: =Data!B11 -> Month1 | B11: =Data!C11 -> N | C11: =Data!D11 -> Mumbai | D11: =Data!E11 -> HappyGrow | E11: =Data!F11 -> 23421 | F11: =Data!G11 -> 23656 | G11: =IF(D11="PowerSip", 135, IF(D11="HappyGrow", 60, "")) -> 60 | H11: =IF(D11="PowerSip", 140, IF(D11="HappyGrow", 70, "")) -> 70 | I11: =E11 * G11 -> 1405260 | J11: =F11 * H11 -> 1655920 | K11: =IF(E11=0, "", I11 / E11) -> 60 | L11: =IF(F11=0, "", J11 / F11) -> 70
A12: =Data!B12 -> Month1 | B12: =Data!C12 -> E | C12: =Data!D12 -> Mumbai | D12: =Data!E12 -> PowerSip | E12: =Data!F12 -> 12469 | F12: =Data!G12 -> 13467 | G12: =IF(D12="PowerSip", 135, IF(D12="HappyGrow", 60, "")) -> 135 | H12: =IF(D12="PowerSip", 140, IF(D12="HappyGrow", 70, "")) -> 140 | I12: =E12 * G12 -> 1683315 | J12: =F12 * H12 -> 1885380 | K12: =IF(E12=0, "", I12 / E12) -> 135 | L12: =IF(F12=0, "", J12 / F12) -> 140
A13: =Data!B13 -> Month1 | B13: =Data!C13 -> E | C13: =Data!D13 -> Mumbai | D13: =Data!E13 -> HappyGrow | E13: =Data!F13 -> 16354 | F13: =Data!G13 -> 16518 | G13: =IF(D13="PowerSip", 135, IF(D13="HappyGrow", 60, "")) -> 60 | H13: =IF(D13="PowerSip", 140, IF(D13="HappyGrow", 70, "")) -> 70 | I13: =E13 * G13 -> 981240 | J13: =F13 * H13 -> 1156260 | K13: =IF(E13=0, "", I13 / E13) -> 60 | L13: =IF(F13=0, "", J13 / F13) -> 70
A14: =Data!B14 -> Month1 | B14: =Data!C14 -> W | C14: =Data!D14 -> Mumbai | D14: =Data!E14 -> PowerSip | E14: =Data!F14 -> 19536 | F14: =Data!G14 -> 21099 | G14: =IF(D14="PowerSip", 135, IF(D14="HappyGrow", 60, "")) -> 135 | H14: =IF(D14="PowerSip", 140, IF(D14="HappyGrow", 70, "")) -> 140 | I14: =E14 * G14 -> 2637360 | J14: =F14 * H14 -> 2953860 | K14: =IF(E14=0, "", I14 / E14) -> 135 | L14: =IF(F14=0, "", J14 / F14) -> 140
A15: =Data!B15 -> Month1 | B15: =Data!C15 -> W | C15: =Data!D15 -> Mumbai | D15: =Data!E15 -> HappyGrow | E15: =Data!F15 -> 11359 | F15: =Data!G15 -> 11587 | G15: =IF(D15="PowerSip", 135, IF(D15="HappyGrow", 60, "")) -> 60 | H15: =IF(D15="PowerSip", 140, IF(D15="HappyGrow", 70, "")) -> 70 | I15: =E15 * G15 -> 681540 | J15: =F15 * H15 -> 811090 | K15: =IF(E15=0, "", I15 / E15) -> 60 | L15: =IF(F15=0, "", J15 / F15) -> 70
A16: =Data!B16 -> Month1 | B16: =Data!C16 -> S | C16: =Data!D16 -> Mumbai | D16: =Data!E16 -> PowerSip | E16: =Data!F16 -> 12062 | F16: =Data!G16 -> 13148 | G16: =IF(D16="PowerSip", 135, IF(D16="HappyGrow", 60, "")) -> 135 | H16: =IF(D16="PowerSip", 140, IF(D16="HappyGrow", 70, "")) -> 140 | I16: =E16 * G16 -> 1628370 | J16: =F16 * H16 -> 1840720 | K16: =IF(E16=0, "", I16 / E16) -> 135 | L16: =IF(F16=0, "", J16 / F16) -> 140
A17: =Data!B17 -> Month1 | B17: =Data!C17 -> S | C17: =Data!D17 -> Mumbai | D17: =Data!E17 -> HappyGrow | E17: =Data!F17 -> 13579 | F17: =Data!G17 -> 13851 | G17: =IF(D17="PowerSip", 135, IF(D17="HappyGrow", 60, "")) -> 60 | H17: =IF(D17="PowerSip", 140, IF(D17="HappyGrow", 70, "")) -> 70 | I17: =E17 * G17 -> 814740 | J17: =F17 * H17 -> 969570 | K17: =IF(E17=0, "", I17 / E17) -> 60 | L17: =IF(F17=0, "", J17 / F17) -> 70
A18: =Data!B18 -> Month1 | B18: =Data!C18 -> N | C18: =Data!D18 -> Bengaluru | D18: =Data!E18 -> PowerSip | E18: =Data!F18 -> 21275 | F18: =Data!G18 -> 23190 | G18: =IF(D18="PowerSip", 135, IF(D18="HappyGrow", 60, "")) -> 135 | H18: =IF(D18="PowerSip", 140, IF(D18="HappyGrow", 70, "")) -> 140 | I18: =E18 * G18 -> 2872125 | J18: =F18 * H18 -> 3246600 | K18: =IF(E18=0, "", I18 / E18) -> 135 | L18: =IF(F18=0, "", J18 / F18) -> 140
A19: =Data!B19 -> Month1 | B19: =Data!C19 -> N | C19: =Data!D19 -> Bengaluru | D19: =Data!E19 -> HappyGrow | E19: =Data!F19 -> 18611 | F19: =Data!G19 -> 18984 | G19: =IF(D19="PowerSip", 135, IF(D19="HappyGrow", 60, "")) -> 60 | H19: =IF(D19="PowerSip", 140, IF(D19="HappyGrow", 70, "")) -> 70 | I19: =E19 * G19 -> 1116660 | J19: =F19 * H19 -> 1328880 | K19: =IF(E19=0, "", I19 / E19) -> 60 | L19: =IF(F19=0, "", J19 / F19) -> 70
A20: =Data!B20 -> Month1 | B20: =Data!C20 -> E | C20: =Data!D20 -> Bengaluru | D20: =Data!E20 -> PowerSip | E20: =Data!F20 -> 24050 | F20: =Data!G20 -> 26215 | G20: =IF(D20="PowerSip", 135, IF(D20="HappyGrow", 60, "")) -> 135 | H20: =IF(D20="PowerSip", 140, IF(D20="HappyGrow", 70, "")) -> 140 | I20: =E20 * G20 -> 3246750 | J20: =F20 * H20 -> 3670100 | K20: =IF(E20=0, "", I20 / E20) -> 135 | L20: =IF(F20=0, "", J20 / F20) -> 140
... A193: =Data!B193 -> Month6 | B193: =Data!C193 -> S | C193: =Data!D193 -> Delhi | D193: =Data!E193 -> HappyGrow | E193: =Data!F193 -> 32072 | F193: =Data!G193 -> 40090 | G193: =IF(D193="PowerSip", 135, IF(D193="HappyGrow", 60, "")) -> 60 | H193: =IF(D193="PowerSip", 140, IF(D193="HappyGrow", 70, "")) -> 70 | I193: =E193 * G193 -> 1924320 | J193: =F193 * H193 -> 2806300 | K193: =IF(E193=0, "", I193 / E193) -> 60 | L193: =IF(F193=0, "", J193 / F193) -> 70
A194: =Data!B194 | B194: =Data!C194 | C194: =Data!D194 | D194: =Data!E194 | E194: =Data!F194 | F194: =Data!G194 | G194: =IF(D194="PowerSip", 135, IF(D194="HappyGrow", 60, "")) | H194: =IF(D194="PowerSip", 140, IF(D194="HappyGrow", 70, ""))
A195: =Data!B195 | B195: =Data!C195 | C195: =Data!D195 | D195: =Data!E195 | E195: =Data!F195 | F195: =Data!G195 | G195: =IF(D195="PowerSip", 135, IF(D195="HappyGrow", 60, "")) | H195: =IF(D195="PowerSip", 140, IF(D195="HappyGrow", 70, ""))
A196: =Data!B196 | B196: =Data!C196 | C196: =Data!D196 | D196: =Data!E196 | E196: =Data!F196 | F196: =Data!G196 | G196: =IF(D196="PowerSip", 135, IF(D196="HappyGrow", 60, "")) | H196: =IF(D196="PowerSip", 140, IF(D196="HappyGrow", 70, ""))
A197: =Data!B197 | B197: =Data!C197 | C197: =Data!D197 | D197: =Data!E197 | E197: =Data!F197 | F197: =Data!G197 | G197: =IF(D197="PowerSip", 135, IF(D197="HappyGrow", 60, "")) | H197: =IF(D197="PowerSip", 140, IF(D197="HappyGrow", 70, ""))
A198: =Data!B198 | B198: =Data!C198 | C198: =Data!D198 | D198: =Data!E198 | E198: =Data!F198 | F198: =Data!G198 | G198: =IF(D198="PowerSip", 135, IF(D198="HappyGrow", 60, "")) | H198: =IF(D198="PowerSip", 140, IF(D198="HappyGrow", 70, ""))
A199: =Data!B199 | B199: =Data!C199 | C199: =Data!D199 | D199: =Data!E199 | E199: =Data!F199 | F199: =Data!G199 | G199: =IF(D199="PowerSip", 135, IF(D199="HappyGrow", 60, "")) | H199: =IF(D199="PowerSip", 140, IF(D199="HappyGrow", 70, ""))
A200: =Data!B200 | B200: =Data!C200 | C200: =Data!D200 | D200: =Data!E200 | E200: =Data!F200 | F200: =Data!G200 | G200: =IF(D200="PowerSip", 135, IF(D200="HappyGrow", 60, "")) | H200: =IF(D200="PowerSip", 140, IF(D200="HappyGrow", 70, ""))
A201: =Data!B201 | B201: =Data!C201 | C201: =Data!D201 | D201: =Data!E201 | E201: =Data!F201 | F201: =Data!G201 | G201: =IF(D201="PowerSip", 135, IF(D201="HappyGrow", 60, "")) | H201: =IF(D201="PowerSip", 140, IF(D201="HappyGrow", 70, ""))
A202: =Data!B202 | B202: =Data!C202 | C202: =Data!D202 | D202: =Data!E202 | E202: =Data!F202 | F202: =Data!G202 | G202: =IF(D202="PowerSip", 135, IF(D202="HappyGrow", 60, "")) | H202: =IF(D202="PowerSip", 140, IF(D202="HappyGrow", 70, ""))
A203: =Data!B203 | B203: =Data!C203 | C203: =Data!D203 | D203: =Data!E203 | E203: =Data!F203 | F203: =Data!G203 | G203: =IF(D203="PowerSip", 135, IF(D203="HappyGrow", 60, "")) | H203: =IF(D203="PowerSip", 140, IF(D203="HappyGrow", 70, ""))
A204: =Data!B204 | B204: =Data!C204 | C204: =Data!D204 | D204: =Data!E204 | E204: =Data!F204 | F204: =Data!G204 | G204: =IF(D204="PowerSip", 135, IF(D204="HappyGrow", 60, "")) | H204: =IF(D204="PowerSip", 140, IF(D204="HappyGrow", 70, ""))
A205: =Data!B205 | B205: =Data!C205 | C205: =Data!D205 | D205: =Data!E205 | E205: =Data!F205 | F205: =Data!G205 | G205: =IF(D205="PowerSip", 135, IF(D205="HappyGrow", 60, "")) | H205: =IF(D205="PowerSip", 140, IF(D205="HappyGrow", 70, ""))
... A270: =Data!B270 | B270: =Data!C270 | C270: =Data!D270 | D270: =Data!E270 | E270: =Data!F270 | F270: =Data!G270 | G270: =IF(D270="PowerSip", 135, IF(D270="HappyGrow", 60, "")) | H270: =IF(D270="PowerSip", 140, IF(D270="HappyGrow", 70, ""))

Sheet Assumption
A1: Quantity
A2: Item | B2: Pack (in ml) | C2: Existing Price (in Rs. per Pack) | D2: New Price (in Rs. per Pack)
A3: PowerSip | B3: 300 | C3: 135 | D3: 140
A4: HappyGrow | B4: 200 | C4: 60 | D4: 70
A7: Material Details of each Pack
A8: PowerSip
A9: Item | B9: Price/litre in Rs. | C9: Material %
A10: Water | B10: 8 | C10: 0.35
A11: Milk | B11: 50 | C11: 0.35
A12: Pea Protein Extract | B12: 400 | C12: 0.1
A13: Coffee Bean Extract | B13: 300 | C13: 0.1
A14: Dates Extract | B14: 90 | C14: 0.05
A15: Monk Fruit Extract | B15: 1100 | C15: 0.02
A16: Other Ingredients | B16: 1200 | C16: 0.03
A18: HappyGrow
A19: Item | B19: Price/kg in Rs. | C19: Material %
A20: Water | B20: 8 | C20: 0.42
A21: Oats Extract | B21: 80 | C21: 0.2
A22: Ragi Extract | B22: 40 | C22: 0.15
A23: Jowar Extract | B23: 29 | C23: 0.07
A24: Bajra Extract | B24: 25 | C24: 0.07
A25: Dates Extract | B25: 90 | C25: 0.06
A26: Other Ingredients | B26: 1200 | C26: 0.03
B28: Existing Pack | C28: New Pack
A29: Pack Cost (in Rs.) | B29: 2 | C29: 3
A30: Processing Cost (in Rs.) | B30: 8 | C30: 8
A32: Factory Expenses (in Rs.)
A33: Factory Rent | B33: 150000
A34: Cold Storage Cost | B34: 75000
A36: MARKETING Expenses (in Rs.) | B36: March Budget | C36: Month on Month Growth%
A37: Old marketing Budget | B37: 80000 | C37: 0.1
A39: Incremental marketing Cost (in Rs.) | B39: 1st Month
A40: Ads Preparation | B40: 10000000
A41: New Design | B41: 10000
A42: Incremental Advertising | B42: 30000000

Sheet Cost-Benefit Analysis
A1: Amount (in Rs) | B1: January | C1: February | D1: March | E1: April | F1: May | G1: June
A2: Contribution
A3: =Contribution_Old!A2 -> Old Plan | B3: =Contribution_Old!B$31 -> 33769679 | C3: =Contribution_Old!C$31 -> 36856628 | D3: =Contribution_Old!D$31 -> 40232112 | E3: =Contribution_Old!E$31 -> 43923260 | F3: =Contribution_Old!F$31 -> 47960310 | G3: =Contribution_Old!G$31 -> 52376138 | H3: =SUM(B3:G3) -> 255118127
A4: =Contribution_New!A2 -> New Plan | B4: =Contribution_New!B$31 -> 39957792 | C4: =Contribution_New!C$31 -> 45981864 | D4: =Contribution_New!D$31 -> 51788976 | E4: =Contribution_New!E$31 -> 59140498 | F4: =Contribution_New!F$31 -> 67713064 | G4: =Contribution_New!G$31 -> 77149409 | H4: =SUM(B4:G4) -> 3.417316e+08
A6: Incremental Contribution | B6: =B$4-B$3 -> 6188113.2 | C6: =C$4-C$3 -> 9125235.8 | D6: =D$4-D$3 -> 11556864 | E6: =E$4-E$3 -> 15217238 | F6: =F$4-F$3 -> 19752754 | G6: =G$4-G$3 -> 24773271 | H6: =SUM(B6:G6) -> 86613477
A8: Incremental Contribution
A9: =Assumption!A40 -> Ads Preparation | B9: =Assumption!B40 -> 10000000 | C9: 0 | D9: 0 | E9: 0 | F9: 0 | G9: 0
A10: =Assumption!A41 -> New Design | B10: =Assumption!B41 -> 10000 | C10: 0 | D10: 0 | E10: 0 | F10: 0 | G10: 0
A11: =Assumption!A42 -> Incremental Advertising | B11: =Assumption!$B$42/6 -> 5000000 | C11: =Assumption!$B$42/6 -> 5000000 | D11: =Assumption!$B$42/6 -> 5000000 | E11: =Assumption!$B$42/6 -> 5000000 | F11: =Assumption!$B$42/6 -> 5000000 | G11: =Assumption!$B$42/6 -> 5000000
A12: Total | B12: =SUM(B9:B11) -> 15010000 | C12: =SUM(C9:C11) -> 5000000 | D12: =SUM(D9:D11) -> 5000000 | E12: =SUM(E9:E11) -> 5000000 | F12: =SUM(F9:F11) -> 5000000 | G12: =SUM(G9:G11) -> 5000000
A14: Incremental Profits | B14: =B$6-B$12 -> -8821886.8 | C14: =C$6-C$12 -> 4125235.8 | D14: =D$6-D$12 -> 6556864.3 | E14: =E$6-E$12 -> 10217238 | F14: =F$6-F$12 -> 14752754 | G14: =G$6-G$12 -> 19773271 | H14: =SUM(B14:G14) -> 46603477

Sheet Dashboard 

Sheet Insight

Sheet Contribution_New
A1: Amount (in Rs) | B1: January | C1: February | D1: March | E1: April | F1: May | G1: June
A2: New Plan
A4: Sales
A5: PowerSip | B5: =SUMIFS('Sales Quantity'!$J:$J, 'Sales Quantity'!$A:$A, Details!A$14, 'Sales Quantity'!$D:$D, $A$5) -> 46463760 | C5: =SUMIFS('Sales Quantity'!$J:$J, 'Sales Quantity'!$A:$A, Details!B$14, 'Sales Quantity'!$D:$D, $A$5) -> 54229420 | D5: =SUMIFS('Sales Quantity'!$J:$J, 'Sales Quantity'!$A:$A, Details!C$14, 'Sales Quantity'!$D:$D, $A$5) -> 61464620 | E5: =SUMIFS('Sales Quantity'!$J:$J, 'Sales Quantity'!$A:$A, Details!D$14, 'Sales Quantity'!$D:$D, $A$5) -> 70967680 | F5: =SUMIFS('Sales Quantity'!$J:$J, 'Sales Quantity'!$A:$A, Details!E$14, 'Sales Quantity'!$D:$D, $A$5) -> 82241600 | G5: =SUMIFS('Sales Quantity'!$J:$J, 'Sales Quantity'!$A:$A, Details!F$14, 'Sales Quantity'!$D:$D, $A$5) -> 94788540
A6: HappyGrow | B6: =SUMIFS('Sales Quantity'!$J:$J, 'Sales Quantity'!$A:$A, Details!A$14, 'Sales Quantity'!$D:$D, $A$6) -> 19270300 | C6: =SUMIFS('Sales Quantity'!$J:$J, 'Sales Quantity'!$A:$A, Details!B$14, 'Sales Quantity'!$D:$D, $A$6) -> 21470890 | D6: =SUMIFS('Sales Quantity'!$J:$J, 'Sales Quantity'!$A:$A, Details!C$14, 'Sales Quantity'!$D:$D, $A$6) -> 23824500 | E6: =SUMIFS('Sales Quantity'!$J:$J, 'Sales Quantity'!$A:$A, Details!D$14, 'Sales Quantity'!$D:$D, $A$6) -> 26485760 | F6: =SUMIFS('Sales Quantity'!$J:$J, 'Sales Quantity'!$A:$A, Details!E$14, 'Sales Quantity'!$D:$D, $A$6) -> 29410780 | G6: =SUMIFS('Sales Quantity'!$J:$J, 'Sales Quantity'!$A:$A, Details!F$14, 'Sales Quantity'!$D:$D, $A$6) -> 32503590
A7: Total | B7: =SUM(B5:B6) -> 65734060 | C7: =SUM(C5:C6) -> 75700310 | D7: =SUM(D5:D6) -> 85289120 | E7: =SUM(E5:E6) -> 97453440 | F7: =SUM(F5:F6) -> 111652380 | G7: =SUM(G5:G6) -> 127292130
A9: Variable Cost
A10: =A5 -> PowerSip
A11: Material Cost | B11: ='Cost-RM'!B$39 -> 15213563 | C11: ='Cost-RM'!C$39 -> 17756262 | D11: ='Cost-RM'!D$39 -> 20125273 | E11: ='Cost-RM'!E$39 -> 23236846 | F11: ='Cost-RM'!F$39 -> 26928250 | G11: ='Cost-RM'!G$39 -> 31036476
A12: Packing Cost | B12: =Assumption!$C$29*'RM Consumed_PowerSip'!B$14 -> 995652 | C12: =Assumption!$C$29*'RM Consumed_PowerSip'!C$14 -> 1162059 | D12: =Assumption!$C$29*'RM Consumed_PowerSip'!D$14 -> 1317099 | E12: =Assumption!$C$29*'RM Consumed_PowerSip'!E$14 -> 1520736 | F12: =Assumption!$C$29*'RM Consumed_PowerSip'!F$14 -> 1762320 | G12: =Assumption!$C$29*'RM Consumed_PowerSip'!G$14 -> 2031183
A13: Processing Cost | B13: =Assumption!$C$30*'RM Consumed_PowerSip'!B$14 -> 2655072 | C13: =Assumption!$C$30*'RM Consumed_PowerSip'!C$14 -> 3098824 | D13: =Assumption!$C$30*'RM Consumed_PowerSip'!D$14 -> 3512264 | E13: =Assumption!$C$30*'RM Consumed_PowerSip'!E$14 -> 4055296 | F13: =Assumption!$C$30*'RM Consumed_PowerSip'!F$14 -> 4699520 | G13: =Assumption!$C$30*'RM Consumed_PowerSip'!G$14 -> 5416488
A14: Total | B14: =SUM(B11:B13) -> 18864287 | C14: =SUM(C11:C13) -> 22017145 | D14: =SUM(D11:D13) -> 24954636 | E14: =SUM(E11:E13) -> 28812878 | F14: =SUM(F11:F13) -> 33390090 | G14: =SUM(G11:G13) -> 38484147
A16: =A6 -> HappyGrow
A17: Material Cost | B17: ='Cost-RM'!B$49 -> 3883791.3 | C17: ='Cost-RM'!C$49 -> 4327304.5 | D17: ='Cost-RM'!D$49 -> 4801657.8 | E17: ='Cost-RM'!E$49 -> 5338015.7 | F17: ='Cost-RM'!F$49 -> 5927532.6 | G17: ='Cost-RM'!G$49 -> 6550866.4
A18: Packing Cost | B18: =Assumption!$C$29*'RM Consumed_HappyGrow'!B$14 -> 825870 | C18: =Assumption!$C$29*'RM Consumed_HappyGrow'!C$14 -> 920181 | D18: =Assumption!$C$29*'RM Consumed_HappyGrow'!D$14 -> 1021050 | E18: =Assumption!$C$29*'RM Consumed_HappyGrow'!E$14 -> 1135104 | F18: =Assumption!$C$29*'RM Consumed_HappyGrow'!F$14 -> 1260462 | G18: =Assumption!$C$29*'RM Consumed_HappyGrow'!G$14 -> 1393011
A19: Processing Cost | B19: =Assumption!$C$30*'RM Consumed_HappyGrow'!B$14 -> 2202320 | C19: =Assumption!$C$30*'RM Consumed_HappyGrow'!C$14 -> 2453816 | D19: =Assumption!$C$30*'RM Consumed_HappyGrow'!D$14 -> 2722800 | E19: =Assumption!$C$30*'RM Consumed_HappyGrow'!E$14 -> 3026944 | F19: =Assumption!$C$30*'RM Consumed_HappyGrow'!F$14 -> 3361232 | G19: =Assumption!$C$30*'RM Consumed_HappyGrow'!G$14 -> 3714696
A20: Total | B20: =SUM(B17:B19) -> 6911981.3 | C20: =SUM(C17:C19) -> 7701301.5 | D20: =SUM(D17:D19) -> 8545507.8 | E20: =SUM(E17:E19) -> 9500063.7 | F20: =SUM(F17:F19) -> 10549227 | G20: =SUM(G17:G19) -> 11658573
A22: Total Variable Cost
A23: =A5 -> PowerSip | B23: =B$14 -> 18864287 | C23: =C$14 -> 22017145 | D23: =D$14 -> 24954636 | E23: =E$14 -> 28812878 | F23: =F$14 -> 33390090 | G23: =G$14 -> 38484147
A24: =A6 -> HappyGrow | B24: =B$20 -> 6911981.3 | C24: =C$20 -> 7701301.5 | D24: =D$20 -> 8545507.8 | E24: =E$20 -> 9500063.7 | F24: =F$20 -> 10549227 | G24: =G$20 -> 11658573
A25: =A22 -> Total Variable Cost | B25: =SUM(B23:B24) -> 25776268 | C25: =SUM(C23:C24) -> 29718446 | D25: =SUM(D23:D24) -> 33500144 | E25: =SUM(E23:E24) -> 38312942 | F25: =SUM(F23:F24) -> 43939316 | G25: =SUM(G23:G24) -> 50142721
A28: Contribution (Sales-Variable Cost)
A29: =A5 -> PowerSip | B29: =B$5-B$23 -> 27599473 | C29: =C$5-C$23 -> 32212275 | D29: =D$5-D$23 -> 36509984 | E29: =E$5-E$23 -> 42154802 | F29: =F$5-F$23 -> 48851510 | G29: =G$5-G$23 -> 56304393
A30: =A6 -> HappyGrow | B30: =B$6-B$24 -> 12358319 | C30: =C$6-C$24 -> 13769588 | D30: =D$6-D$24 -> 15278992 | E30: =E$6-E$24 -> 16985696 | F30: =F$6-F$24 -> 18861553 | G30: =G$6-G$24 -> 20845017
A31: Total | B31: =SUM(B29:B30) -> 39957792 | C31: =SUM(C29:C30) -> 45981864 | D31: =SUM(D29:D30) -> 51788976 | E31: =SUM(E29:E30) -> 59140498 | F31: =SUM(F29:F30) -> 67713064 | G31: =SUM(G29:G30) -> 77149409
A33: Contribution Per Unit(in Rs.)
A34: =A5 -> PowerSip | B34: =Assumption!$D$3-('Cost-RM'!B$52+Assumption!$C$29+Assumption!$C$30) -> 83.16 | C34: =Assumption!$D$3-('Cost-RM'!C$52+Assumption!$C$29+Assumption!$C$30) -> 83.16 | D34: =Assumption!$D$3-('Cost-RM'!D$52+Assumption!$C$29+Assumption!$C$30) -> 83.16 | E34: =Assumption!$D$3-('Cost-RM'!E$52+Assumption!$C$29+Assumption!$C$30) -> 83.16 | F34: =Assumption!$D$3-('Cost-RM'!F$52+Assumption!$C$29+Assumption!$C$30) -> 83.16 | G34: =Assumption!$D$3-('Cost-RM'!G$52+Assumption!$C$29+Assumption!$C$30) -> 83.16
A35: =A6 -> HappyGrow | B35: =Assumption!$D$4-('Cost-RM'!B$53+Assumption!$C$29+Assumption!$C$30) -> 44.892 | C35: =Assumption!$D$4-('Cost-RM'!C$53+Assumption!$C$29+Assumption!$C$30) -> 44.892 | D35: =Assumption!$D$4-('Cost-RM'!D$53+Assumption!$C$29+Assumption!$C$30) -> 44.892 | E35: =Assumption!$D$4-('Cost-RM'!E$53+Assumption!$C$29+Assumption!$C$30) -> 44.892 | F35: =Assumption!$D$4-('Cost-RM'!F$53+Assumption!$C$29+Assumption!$C$30) -> 44.892 | G35: =Assumption!$D$4-('Cost-RM'!G$53+Assumption!$C$29+Assumption!$C$30) -> 44.892
A36: Total | B36: =SUM(B34:B35) -> 128.052 | C36: =SUM(C34:C35) -> 128.052 | D36: =SUM(D34:D35) -> 128.052 | E36: =SUM(E34:E35) -> 128.052 | F36: =SUM(F34:F35) -> 128.052 | G36: =SUM(G34:G35) -> 128.052

Sheet Contribution_Old
A1: Amount (in Rs) | B1: January | C1: February | D1: March | E1: April | F1: May | G1: June
A2: Old Plan
A4: Sales
A5: PowerSip | B5: =SUMIFS('Sales Quantity'!$I:$I, 'Sales Quantity'!$A:$A, Details!A$14, 'Sales Quantity'!$D:$D, $A$5) -> 41098860 | C5: =SUMIFS('Sales Quantity'!$I:$I, 'Sales Quantity'!$A:$A, Details!B$14, 'Sales Quantity'!$D:$D, $A$5) -> 45208935 | D5: =SUMIFS('Sales Quantity'!$I:$I, 'Sales Quantity'!$A:$A, Details!C$14, 'Sales Quantity'!$D:$D, $A$5) -> 49730220 | E5: =SUMIFS('Sales Quantity'!$I:$I, 'Sales Quantity'!$A:$A, Details!D$14, 'Sales Quantity'!$D:$D, $A$5) -> 54703350 | F5: =SUMIFS('Sales Quantity'!$I:$I, 'Sales Quantity'!$A:$A, Details!E$14, 'Sales Quantity'!$D:$D, $A$5) -> 60173955 | G5: =SUMIFS('Sales Quantity'!$I:$I, 'Sales Quantity'!$A:$A, Details!F$14, 'Sales Quantity'!$D:$D, $A$5) -> 66191310
A6: HappyGrow | B6: =SUMIFS('Sales Quantity'!$I:$I, 'Sales Quantity'!$A:$A, Details!A$14, 'Sales Quantity'!$D:$D, $A$6) -> 16166040 | C6: =SUMIFS('Sales Quantity'!$I:$I, 'Sales Quantity'!$A:$A, Details!B$14, 'Sales Quantity'!$D:$D, $A$6) -> 17297640 | D6: =SUMIFS('Sales Quantity'!$I:$I, 'Sales Quantity'!$A:$A, Details!C$14, 'Sales Quantity'!$D:$D, $A$6) -> 18508500 | E6: =SUMIFS('Sales Quantity'!$I:$I, 'Sales Quantity'!$A:$A, Details!D$14, 'Sales Quantity'!$D:$D, $A$6) -> 19804140 | F6: =SUMIFS('Sales Quantity'!$I:$I, 'Sales Quantity'!$A:$A, Details!E$14, 'Sales Quantity'!$D:$D, $A$6) -> 21190380 | G6: =SUMIFS('Sales Quantity'!$I:$I, 'Sales Quantity'!$A:$A, Details!F$14, 'Sales Quantity'!$D:$D, $A$6) -> 22673880
A7: Total | B7: =SUM(B5:B6) -> 57264900 | C7: =SUM(C5:C6) -> 62506575 | D7: =SUM(D5:D6) -> 68238720 | E7: =SUM(E5:E6) -> 74507490 | F7: =SUM(F5:F6) -> 81364335 | G7: =SUM(G5:G6) -> 88865190
A9: Variable Cost
A10: =A5 -> PowerSip
A11: Material Cost | B11: ='Cost-RM'!B$12 -> 13955346 | C11: ='Cost-RM'!C$12 -> 15350945 | D11: ='Cost-RM'!D$12 -> 16886172 | E11: ='Cost-RM'!E$12 -> 18574826 | F11: ='Cost-RM'!F$12 -> 20432401 | G11: ='Cost-RM'!G$12 -> 22475627
A12: Packing Cost | B12: =Assumption!$B$29*'RM Consumed_PowerSip'!B$13 -> 608872 | C12: =Assumption!$B$29*'RM Consumed_PowerSip'!C$13 -> 669762 | D12: =Assumption!$B$29*'RM Consumed_PowerSip'!D$13 -> 736744 | E12: =Assumption!$B$29*'RM Consumed_PowerSip'!E$13 -> 810420 | F12: =Assumption!$B$29*'RM Consumed_PowerSip'!F$13 -> 891466 | G12: =Assumption!$B$29*'RM Consumed_PowerSip'!G$13 -> 980612
A13: Processing Cost | B13: =Assumption!$B$30*'RM Consumed_PowerSip'!B$13 -> 2435488 | C13: =Assumption!$B$30*'RM Consumed_PowerSip'!C$13 -> 2679048 | D13: =Assumption!$B$30*'RM Consumed_PowerSip'!D$13 -> 2946976 | E13: =Assumption!$B$30*'RM Consumed_PowerSip'!E$13 -> 3241680 | F13: =Assumption!$B$30*'RM Consumed_PowerSip'!F$13 -> 3565864 | G13: =Assumption!$B$30*'RM Consumed_PowerSip'!G$13 -> 3922448
A14: Total | B14: =SUM(B11:B13) -> 16999706 | C14: =SUM(C11:C13) -> 18699755 | D14: =SUM(D11:D13) -> 20569892 | E14: =SUM(E11:E13) -> 22626926 | F14: =SUM(F11:F13) -> 24889731 | G14: =SUM(G11:G13) -> 27378687
A16: =A6 -> HappyGrow
A17: Material Cost | B17: ='Cost-RM'!B$22 -> 3801174.9 | C17: ='Cost-RM'!C$22 -> 4067251.8 | D17: ='Cost-RM'!D$22 -> 4351965.3 | E17: ='Cost-RM'!E$22 -> 4656613.5 | F17: ='Cost-RM'!F$22 -> 4982564.7 | G17: ='Cost-RM'!G$22 -> 5331385
A18: Packing Cost | B18: =Assumption!$B$29*'RM Consumed_HappyGrow'!B$13 -> 538868 | C18: =Assumption!$B$29*'RM Consumed_HappyGrow'!C$13 -> 576588 | D18: =Assumption!$B$29*'RM Consumed_HappyGrow'!D$13 -> 616950 | E18: =Assumption!$B$29*'RM Consumed_HappyGrow'!E$13 -> 660138 | F18: =Assumption!$B$29*'RM Consumed_HappyGrow'!F$13 -> 706346 | G18: =Assumption!$B$29*'RM Consumed_HappyGrow'!G$13 -> 755796
A19: Processing Cost | B19: =Assumption!$B$30*'RM Consumed_HappyGrow'!B$13 -> 2155472 | C19: =Assumption!$B$30*'RM Consumed_HappyGrow'!C$13 -> 2306352 | D19: =Assumption!$B$30*'RM Consumed_HappyGrow'!D$13 -> 2467800 | E19: =Assumption!$B$30*'RM Consumed_HappyGrow'!E$13 -> 2640552 | F19: =Assumption!$B$30*'RM Consumed_HappyGrow'!F$13 -> 2825384 | G19: =Assumption!$B$30*'RM Consumed_HappyGrow'!G$13 -> 3023184
A20: Total | B20: =SUM(B17:B19) -> 6495514.9 | C20: =SUM(C17:C19) -> 6950191.8 | D20: =SUM(D17:D19) -> 7436715.3 | E20: =SUM(E17:E19) -> 7957303.5 | F20: =SUM(F17:F19) -> 8514294.7 | G20: =SUM(G17:G19) -> 9110365
A22: Total Variable Cost
A23: =A5 -> PowerSip | B23: =B$14 -> 16999706 | C23: =C$14 -> 18699755 | D23: =D$14 -> 20569892 | E23: =E$14 -> 22626926 | F23: =F$14 -> 24889731 | G23: =G$14 -> 27378687
A24: =A6 -> HappyGrow | B24: =B$20 -> 6495514.9 | C24: =C$20 -> 6950191.8 | D24: =D$20 -> 7436715.3 | E24: =E$20 -> 7957303.5 | F24: =F$20 -> 8514294.7 | G24: =G$20 -> 9110365
A25: =A22 -> Total Variable Cost | B25: =SUM(B23:B24) -> 23495221 | C25: =SUM(C23:C24) -> 25649947 | D25: =SUM(D23:D24) -> 28006608 | E25: =SUM(E23:E24) -> 30584230 | F25: =SUM(F23:F24) -> 33404025 | G25: =SUM(G23:G24) -> 36489052
A28: Contribution (Sales-Variable Cost)
A29: =A5 -> PowerSip | B29: =B$5-B$23 -> 24099154 | C29: =C$5-C$23 -> 26509180 | D29: =D$5-D$23 -> 29160328 | E29: =E$5-E$23 -> 32076424 | F29: =F$5-F$23 -> 35284224 | G29: =G$5-G$23 -> 38812623
A30: =A6 -> HappyGrow | B30: =B$6-B$24 -> 9670525.1 | C30: =C$6-C$24 -> 10347448 | D30: =D$6-D$24 -> 11071785 | E30: =E$6-E$24 -> 11846837 | F30: =F$6-F$24 -> 12676085 | G30: =G$6-G$24 -> 13563515
A31: Total | B31: =SUM(B29:B30) -> 33769679 | C31: =SUM(C29:C30) -> 36856628 | D31: =SUM(D29:D30) -> 40232112 | E31: =SUM(E29:E30) -> 43923260 | F31: =SUM(F29:F30) -> 47960310 | G31: =SUM(G29:G30) -> 52376138
A33: Contribution Per Unit(in Rs.)
A34: =A5 -> PowerSip | B34: =Assumption!$C$3-('Cost-RM'!B$52+Assumption!$B$29+Assumption!$B$30) -> 79.16 | C34: =Assumption!$C$3-('Cost-RM'!C$52+Assumption!$B$29+Assumption!$B$30) -> 79.16 | D34: =Assumption!$C$3-('Cost-RM'!D$52+Assumption!$B$29+Assumption!$B$30) -> 79.16 | E34: =Assumption!$C$3-('Cost-RM'!E$52+Assumption!$B$29+Assumption!$B$30) -> 79.16 | F34: =Assumption!$C$3-('Cost-RM'!F$52+Assumption!$B$29+Assumption!$B$30) -> 79.16 | G34: =Assumption!$C$3-('Cost-RM'!G$52+Assumption!$B$29+Assumption!$B$30) -> 79.16
A35: =A6 -> HappyGrow | B35: =Assumption!$C$4-('Cost-RM'!B$53+Assumption!$B$29+Assumption!$B$30) -> 35.892 | C35: =Assumption!$C$4-('Cost-RM'!C$53+Assumption!$B$29+Assumption!$B$30) -> 35.892 | D35: =Assumption!$C$4-('Cost-RM'!D$53+Assumption!$B$29+Assumption!$B$30) -> 35.892 | E35: =Assumption!$C$4-('Cost-RM'!E$53+Assumption!$B$29+Assumption!$B$30) -> 35.892 | F35: =Assumption!$C$4-('Cost-RM'!F$53+Assumption!$B$29+Assumption!$B$30) -> 35.892 | G35: =Assumption!$C$4-('Cost-RM'!G$53+Assumption!$B$29+Assumption!$B$30) -> 35.892
A36: Total | B36: =SUM(B34:B35) -> 115.052 | C36: =SUM(C34:C35) -> 115.052 | D36: =SUM(D34:D35) -> 115.052 | E36: =SUM(E34:E35) -> 115.052 | F36: =SUM(F34:F35) -> 115.052 | G36: =SUM(G34:G35) -> 115.052

Sheet Cost-RM
A1: Cost In(Rs) | B1: =Details!A15 -> January | C1: =Details!B15 -> February | D1: =Details!C15 -> March | E1: =Details!D15 -> April | F1: =Details!E15 -> May | G1: =Details!F15 -> June
A2: Old Plan
A4: =Assumption!A8 -> PowerSip
A5: =Assumption!A10 -> Water | B5: =(Assumption!$C10 * Assumption!$B$3 *'RM Consumed_PowerSip'!B$13)*Assumption!$B10/1000 -> 255726.24 | C5: =(Assumption!$C10 * Assumption!$B$3 *'RM Consumed_PowerSip'!C$13)*Assumption!$B10/1000 -> 281300.04 | D5: =(Assumption!$C10 * Assumption!$B$3 *'RM Consumed_PowerSip'!D$13)*Assumption!$B10/1000 -> 309432.48 | E5: =(Assumption!$C10 * Assumption!$B$3 *'RM Consumed_PowerSip'!E$13)*Assumption!$B10/1000 -> 340376.4 | F5: =(Assumption!$C10 * Assumption!$B$3 *'RM Consumed_PowerSip'!F$13)*Assumption!$B10/1000 -> 374415.72 | G5: =(Assumption!$C10 * Assumption!$B$3 *'RM Consumed_PowerSip'!G$13)*Assumption!$B10/1000 -> 411857.04
A6: =Assumption!A11 -> Milk | B6: =(Assumption!$C11 * Assumption!$B$3 *'RM Consumed_PowerSip'!B$13)*Assumption!$B11/1000 -> 1598289 | C6: =(Assumption!$C11 * Assumption!$B$3 *'RM Consumed_PowerSip'!C$13)*Assumption!$B11/1000 -> 1758125.2 | D6: =(Assumption!$C11 * Assumption!$B$3 *'RM Consumed_PowerSip'!D$13)*Assumption!$B11/1000 -> 1933953 | E6: =(Assumption!$C11 * Assumption!$B$3 *'RM Consumed_PowerSip'!E$13)*Assumption!$B11/1000 -> 2127352.5 | F6: =(Assumption!$C11 * Assumption!$B$3 *'RM Consumed_PowerSip'!F$13)*Assumption!$B11/1000 -> 2340098.2 | G6: =(Assumption!$C11 * Assumption!$B$3 *'RM Consumed_PowerSip'!G$13)*Assumption!$B11/1000 -> 2574106.5
A7: =Assumption!A12 -> Pea Protein Extract | B7: =(Assumption!$C12 * Assumption!$B$3 *'RM Consumed_PowerSip'!B$13)*Assumption!$B12/1000 -> 3653232 | C7: =(Assumption!$C12 * Assumption!$B$3 *'RM Consumed_PowerSip'!C$13)*Assumption!$B12/1000 -> 4018572 | D7: =(Assumption!$C12 * Assumption!$B$3 *'RM Consumed_PowerSip'!D$13)*Assumption!$B12/1000 -> 4420464 | E7: =(Assumption!$C12 * Assumption!$B$3 *'RM Consumed_PowerSip'!E$13)*Assumption!$B12/1000 -> 4862520 | F7: =(Assumption!$C12 * Assumption!$B$3 *'RM Consumed_PowerSip'!F$13)*Assumption!$B12/1000 -> 5348796 | G7: =(Assumption!$C12 * Assumption!$B$3 *'RM Consumed_PowerSip'!G$13)*Assumption!$B12/1000 -> 5883672
A8: =Assumption!A13 -> Coffee Bean Extract | B8: =(Assumption!$C13 * Assumption!$B$3 *'RM Consumed_PowerSip'!B$13)*Assumption!$B13/1000 -> 2739924 | C8: =(Assumption!$C13 * Assumption!$B$3 *'RM Consumed_PowerSip'!C$13)*Assumption!$B13/1000 -> 3013929 | D8: =(Assumption!$C13 * Assumption!$B$3 *'RM Consumed_PowerSip'!D$13)*Assumption!$B13/1000 -> 3315348 | E8: =(Assumption!$C13 * Assumption!$B$3 *'RM Consumed_PowerSip'!E$13)*Assumption!$B13/1000 -> 3646890 | F8: =(Assumption!$C13 * Assumption!$B$3 *'RM Consumed_PowerSip'!F$13)*Assumption!$B13/1000 -> 4011597 | G8: =(Assumption!$C13 * Assumption!$B$3 *'RM Consumed_PowerSip'!G$13)*Assumption!$B13/1000 -> 4412754
A9: =Assumption!A14 -> Dates Extract | B9: =(Assumption!$C14 * Assumption!$B$3 *'RM Consumed_PowerSip'!B$13)*Assumption!$B14/1000 -> 410988.6 | C9: =(Assumption!$C14 * Assumption!$B$3 *'RM Consumed_PowerSip'!C$13)*Assumption!$B14/1000 -> 452089.35 | D9: =(Assumption!$C14 * Assumption!$B$3 *'RM Consumed_PowerSip'!D$13)*Assumption!$B14/1000 -> 497302.2 | E9: =(Assumption!$C14 * Assumption!$B$3 *'RM Consumed_PowerSip'!E$13)*Assumption!$B14/1000 -> 547033.5 | F9: =(Assumption!$C14 * Assumption!$B$3 *'RM Consumed_PowerSip'!F$13)*Assumption!$B14/1000 -> 601739.55 | G9: =(Assumption!$C14 * Assumption!$B$3 *'RM Consumed_PowerSip'!G$13)*Assumption!$B14/1000 -> 661913.1
A10: =Assumption!A15 -> Monk Fruit Extract | B10: =(Assumption!$C15 * Assumption!$B$3 *'RM Consumed_PowerSip'!B$13)*Assumption!$B15/1000 -> 2009277.6 | C10: =(Assumption!$C15 * Assumption!$B$3 *'RM Consumed_PowerSip'!C$13)*Assumption!$B15/1000 -> 2210214.6 | D10: =(Assumption!$C15 * Assumption!$B$3 *'RM Consumed_PowerSip'!D$13)*Assumption!$B15/1000 -> 2431255.2 | E10: =(Assumption!$C15 * Assumption!$B$3 *'RM Consumed_PowerSip'!E$13)*Assumption!$B15/1000 -> 2674386 | F10: =(Assumption!$C15 * Assumption!$B$3 *'RM Consumed_PowerSip'!F$13)*Assumption!$B15/1000 -> 2941837.8 | G10: =(Assumption!$C15 * Assumption!$B$3 *'RM Consumed_PowerSip'!G$13)*Assumption!$B15/1000 -> 3236019.6
A11: =Assumption!A16 -> Other Ingredients | B11: =(Assumption!$C16 * Assumption!$B$3 *'RM Consumed_PowerSip'!B$13)*Assumption!$B16/1000 -> 3287908.8 | C11: =(Assumption!$C16 * Assumption!$B$3 *'RM Consumed_PowerSip'!C$13)*Assumption!$B16/1000 -> 3616714.8 | D11: =(Assumption!$C16 * Assumption!$B$3 *'RM Consumed_PowerSip'!D$13)*Assumption!$B16/1000 -> 3978417.6 | E11: =(Assumption!$C16 * Assumption!$B$3 *'RM Consumed_PowerSip'!E$13)*Assumption!$B16/1000 -> 4376268 | F11: =(Assumption!$C16 * Assumption!$B$3 *'RM Consumed_PowerSip'!F$13)*Assumption!$B16/1000 -> 4813916.4 | G11: =(Assumption!$C16 * Assumption!$B$3 *'RM Consumed_PowerSip'!G$13)*Assumption!$B16/1000 -> 5295304.8
A12: Total | B12: =SUM(B5:B11) -> 13955346 | C12: =SUM(C5:C11) -> 15350945 | D12: =SUM(D5:D11) -> 16886172 | E12: =SUM(E5:E11) -> 18574826 | F12: =SUM(F5:F11) -> 20432401 | G12: =SUM(G5:G11) -> 22475627
A13: =Assumption!A17
A14: =Assumption!A18 -> HappyGrow
A15: =Assumption!A20 -> Water | B15: =(Assumption!$C20*Assumption!$B$4*'RM Consumed_HappyGrow'!B$13)*Assumption!$B20/1000 -> 181059.65 | C15: =(Assumption!$C20*Assumption!$B$4*'RM Consumed_HappyGrow'!C$13)*Assumption!$B20/1000 -> 193733.57 | D15: =(Assumption!$C20*Assumption!$B$4*'RM Consumed_HappyGrow'!D$13)*Assumption!$B20/1000 -> 207295.2 | E15: =(Assumption!$C20*Assumption!$B$4*'RM Consumed_HappyGrow'!E$13)*Assumption!$B20/1000 -> 221806.37 | F15: =(Assumption!$C20*Assumption!$B$4*'RM Consumed_HappyGrow'!F$13)*Assumption!$B20/1000 -> 237332.26 | G15: =(Assumption!$C20*Assumption!$B$4*'RM Consumed_HappyGrow'!G$13)*Assumption!$B20/1000 -> 253947.46
A16: =Assumption!A21 -> Oats Extract | B16: =(Assumption!$C21*Assumption!$B$4*'RM Consumed_HappyGrow'!B$13)*Assumption!$B21/1000 -> 862188.8 | C16: =(Assumption!$C21*Assumption!$B$4*'RM Consumed_HappyGrow'!C$13)*Assumption!$B21/1000 -> 922540.8 | D16: =(Assumption!$C21*Assumption!$B$4*'RM Consumed_HappyGrow'!D$13)*Assumption!$B21/1000 -> 987120 | E16: =(Assumption!$C21*Assumption!$B$4*'RM Consumed_HappyGrow'!E$13)*Assumption!$B21/1000 -> 1056220.8 | F16: =(Assumption!$C21*Assumption!$B$4*'RM Consumed_HappyGrow'!F$13)*Assumption!$B21/1000 -> 1130153.6 | G16: =(Assumption!$C21*Assumption!$B$4*'RM Consumed_HappyGrow'!G$13)*Assumption!$B21/1000 -> 1209273.6
A17: =Assumption!A22 -> Ragi Extract | B17: =(Assumption!$C22*Assumption!$B$4*'RM Consumed_HappyGrow'!B$13)*Assumption!$B22/1000 -> 323320.8 | C17: =(Assumption!$C22*Assumption!$B$4*'RM Consumed_HappyGrow'!C$13)*Assumption!$B22/1000 -> 345952.8 | D17: =(Assumption!$C22*Assumption!$B$4*'RM Consumed_HappyGrow'!D$13)*Assumption!$B22/1000 -> 370170 | E17: =(Assumption!$C22*Assumption!$B$4*'RM Consumed_HappyGrow'!E$13)*Assumption!$B22/1000 -> 396082.8 | F17: =(Assumption!$C22*Assumption!$B$4*'RM Consumed_HappyGrow'!F$13)*Assumption!$B22/1000 -> 423807.6 | G17: =(Assumption!$C22*Assumption!$B$4*'RM Consumed_HappyGrow'!G$13)*Assumption!$B22/1000 -> 453477.6
A18: =Assumption!A23 -> Jowar Extract | B18: =(Assumption!$C23*Assumption!$B$4*'RM Consumed_HappyGrow'!B$13)*Assumption!$B23/1000 -> 109390.2 | C18: =(Assumption!$C23*Assumption!$B$4*'RM Consumed_HappyGrow'!C$13)*Assumption!$B23/1000 -> 117047.36 | D18: =(Assumption!$C23*Assumption!$B$4*'RM Consumed_HappyGrow'!D$13)*Assumption!$B23/1000 -> 125240.85 | E18: =(Assumption!$C23*Assumption!$B$4*'RM Consumed_HappyGrow'!E$13)*Assumption!$B23/1000 -> 134008.01 | F18: =(Assumption!$C23*Assumption!$B$4*'RM Consumed_HappyGrow'!F$13)*Assumption!$B23/1000 -> 143388.24 | G18: =(Assumption!$C23*Assumption!$B$4*'RM Consumed_HappyGrow'!G$13)*Assumption!$B23/1000 -> 153426.59
A19: =Assumption!A24 -> Bajra Extract | B19: =(Assumption!$C24*Assumption!$B$4*'RM Consumed_HappyGrow'!B$13)*Assumption!$B24/1000 -> 94301.9 | C19: =(Assumption!$C24*Assumption!$B$4*'RM Consumed_HappyGrow'!C$13)*Assumption!$B24/1000 -> 100902.9 | D19: =(Assumption!$C24*Assumption!$B$4*'RM Consumed_HappyGrow'!D$13)*Assumption!$B24/1000 -> 107966.25 | E19: =(Assumption!$C24*Assumption!$B$4*'RM Consumed_HappyGrow'!E$13)*Assumption!$B24/1000 -> 115524.15 | F19: =(Assumption!$C24*Assumption!$B$4*'RM Consumed_HappyGrow'!F$13)*Assumption!$B24/1000 -> 123610.55 | G19: =(Assumption!$C24*Assumption!$B$4*'RM Consumed_HappyGrow'!G$13)*Assumption!$B24/1000 -> 132264.3
A20: =Assumption!A25 -> Dates Extract | B20: =(Assumption!$C25*Assumption!$B$4*'RM Consumed_HappyGrow'!B$13)*Assumption!$B25/1000 -> 290988.72 | C20: =(Assumption!$C25*Assumption!$B$4*'RM Consumed_HappyGrow'!C$13)*Assumption!$B25/1000 -> 311357.52 | D20: =(Assumption!$C25*Assumption!$B$4*'RM Consumed_HappyGrow'!D$13)*Assumption!$B25/1000 -> 333153 | E20: =(Assumption!$C25*Assumption!$B$4*'RM Consumed_HappyGrow'!E$13)*Assumption!$B25/1000 -> 356474.52 | F20: =(Assumption!$C25*Assumption!$B$4*'RM Consumed_HappyGrow'!F$13)*Assumption!$B25/1000 -> 381426.84 | G20: =(Assumption!$C25*Assumption!$B$4*'RM Consumed_HappyGrow'!G$13)*Assumption!$B25/1000 -> 408129.84
A21: =Assumption!A26 -> Other Ingredients | B21: =(Assumption!$C26*Assumption!$B$4*'RM Consumed_HappyGrow'!B$13)*Assumption!$B26/1000 -> 1939924.8 | C21: =(Assumption!$C26*Assumption!$B$4*'RM Consumed_HappyGrow'!C$13)*Assumption!$B26/1000 -> 2075716.8 | D21: =(Assumption!$C26*Assumption!$B$4*'RM Consumed_HappyGrow'!D$13)*Assumption!$B26/1000 -> 2221020 | E21: =(Assumption!$C26*Assumption!$B$4*'RM Consumed_HappyGrow'!E$13)*Assumption!$B26/1000 -> 2376496.8 | F21: =(Assumption!$C26*Assumption!$B$4*'RM Consumed_HappyGrow'!F$13)*Assumption!$B26/1000 -> 2542845.6 | G21: =(Assumption!$C26*Assumption!$B$4*'RM Consumed_HappyGrow'!G$13)*Assumption!$B26/1000 -> 2720865.6
A22: Total | B22: =SUM(B15:B21) -> 3801174.9 | C22: =SUM(C15:C21) -> 4067251.8 | D22: =SUM(D15:D21) -> 4351965.3 | E22: =SUM(E15:E21) -> 4656613.5 | F22: =SUM(F15:F21) -> 4982564.7 | G22: =SUM(G15:G21) -> 5331385
A24: Cost Per Unit (Rs.)
A25: =A4 -> PowerSip | B25: =(B$12/'RM Consumed_PowerSip'!B$13) -> 45.84 | C25: =(C$12/'RM Consumed_PowerSip'!C$13) -> 45.84 | D25: =(D$12/'RM Consumed_PowerSip'!D$13) -> 45.84 | E25: =(E$12/'RM Consumed_PowerSip'!E$13) -> 45.84 | F25: =(F$12/'RM Consumed_PowerSip'!F$13) -> 45.84 | G25: =(G$12/'RM Consumed_PowerSip'!G$13) -> 45.84
A26: =A14 -> HappyGrow | B26: =(B22/'RM Consumed_HappyGrow'!B13) -> 14.108 | C26: =(C22/'RM Consumed_HappyGrow'!C13) -> 14.108 | D26: =(D22/'RM Consumed_HappyGrow'!D13) -> 14.108 | E26: =(E22/'RM Consumed_HappyGrow'!E13) -> 14.108 | F26: =(F22/'RM Consumed_HappyGrow'!F13) -> 14.108 | G26: =(G22/'RM Consumed_HappyGrow'!G13) -> 14.108
A29: New Plan
A31: =Assumption!A8 -> PowerSip
A32: =Assumption!A10 -> Water | B32: =(Assumption!$C10*Assumption!$B$3*'RM Consumed_PowerSip'!B$14)*Assumption!$B10/1000 -> 278782.56 | C32: =(Assumption!$C10*Assumption!$B$3*'RM Consumed_PowerSip'!C$14)*Assumption!$B10/1000 -> 325376.52 | D32: =(Assumption!$C10*Assumption!$B$3*'RM Consumed_PowerSip'!D$14)*Assumption!$B10/1000 -> 368787.72 | E32: =(Assumption!$C10*Assumption!$B$3*'RM Consumed_PowerSip'!E$14)*Assumption!$B10/1000 -> 425806.08 | F32: =(Assumption!$C10*Assumption!$B$3*'RM Consumed_PowerSip'!F$14)*Assumption!$B10/1000 -> 493449.6 | G32: =(Assumption!$C10*Assumption!$B$3*'RM Consumed_PowerSip'!G$14)*Assumption!$B10/1000 -> 568731.24
A33: =Assumption!A11 -> Milk | B33: =(Assumption!$C11*Assumption!$B$3*'RM Consumed_PowerSip'!B$14)*Assumption!$B11/1000 -> 1742391 | C33: =(Assumption!$C11*Assumption!$B$3*'RM Consumed_PowerSip'!C$14)*Assumption!$B11/1000 -> 2033603.2 | D33: =(Assumption!$C11*Assumption!$B$3*'RM Consumed_PowerSip'!D$14)*Assumption!$B11/1000 -> 2304923.2 | E33: =(Assumption!$C11*Assumption!$B$3*'RM Consumed_PowerSip'!E$14)*Assumption!$B11/1000 -> 2661288 | F33: =(Assumption!$C11*Assumption!$B$3*'RM Consumed_PowerSip'!F$14)*Assumption!$B11/1000 -> 3084060 | G33: =(Assumption!$C11*Assumption!$B$3*'RM Consumed_PowerSip'!G$14)*Assumption!$B11/1000 -> 3554570.2
A34: =Assumption!A12 -> Pea Protein Extract | B34: =(Assumption!$C12*Assumption!$B$3*'RM Consumed_PowerSip'!B$14)*Assumption!$B12/1000 -> 3982608 | C34: =(Assumption!$C12*Assumption!$B$3*'RM Consumed_PowerSip'!C$14)*Assumption!$B12/1000 -> 4648236 | D34: =(Assumption!$C12*Assumption!$B$3*'RM Consumed_PowerSip'!D$14)*Assumption!$B12/1000 -> 5268396 | E34: =(Assumption!$C12*Assumption!$B$3*'RM Consumed_PowerSip'!E$14)*Assumption!$B12/1000 -> 6082944 | F34: =(Assumption!$C12*Assumption!$B$3*'RM Consumed_PowerSip'!F$14)*Assumption!$B12/1000 -> 7049280 | G34: =(Assumption!$C12*Assumption!$B$3*'RM Consumed_PowerSip'!G$14)*Assumption!$B12/1000 -> 8124732
A35: =Assumption!A13 -> Coffee Bean Extract | B35: =(Assumption!$C13*Assumption!$B$3*'RM Consumed_PowerSip'!B$14)*Assumption!$B13/1000 -> 2986956 | C35: =(Assumption!$C13*Assumption!$B$3*'RM Consumed_PowerSip'!C$14)*Assumption!$B13/1000 -> 3486177 | D35: =(Assumption!$C13*Assumption!$B$3*'RM Consumed_PowerSip'!D$14)*Assumption!$B13/1000 -> 3951297 | E35: =(Assumption!$C13*Assumption!$B$3*'RM Consumed_PowerSip'!E$14)*Assumption!$B13/1000 -> 4562208 | F35: =(Assumption!$C13*Assumption!$B$3*'RM Consumed_PowerSip'!F$14)*Assumption!$B13/1000 -> 5286960 | G35: =(Assumption!$C13*Assumption!$B$3*'RM Consumed_PowerSip'!G$14)*Assumption!$B13/1000 -> 6093549
A36: =Assumption!A14 -> Dates Extract | B36: =(Assumption!$C14*Assumption!$B$3*'RM Consumed_PowerSip'!B$14)*Assumption!$B14/1000 -> 448043.4 | C36: =(Assumption!$C14*Assumption!$B$3*'RM Consumed_PowerSip'!C$14)*Assumption!$B14/1000 -> 522926.55 | D36: =(Assumption!$C14*Assumption!$B$3*'RM Consumed_PowerSip'!D$14)*Assumption!$B14/1000 -> 592694.55 | E36: =(Assumption!$C14*Assumption!$B$3*'RM Consumed_PowerSip'!E$14)*Assumption!$B14/1000 -> 684331.2 | F36: =(Assumption!$C14*Assumption!$B$3*'RM Consumed_PowerSip'!F$14)*Assumption!$B14/1000 -> 793044 | G36: =(Assumption!$C14*Assumption!$B$3*'RM Consumed_PowerSip'!G$14)*Assumption!$B14/1000 -> 914032.35
A37: =Assumption!A15 -> Monk Fruit Extract | B37: =(Assumption!$C15*Assumption!$B$3*'RM Consumed_PowerSip'!B$14)*Assumption!$B15/1000 -> 2190434.4 | C37: =(Assumption!$C15*Assumption!$B$3*'RM Consumed_PowerSip'!C$14)*Assumption!$B15/1000 -> 2556529.8 | D37: =(Assumption!$C15*Assumption!$B$3*'RM Consumed_PowerSip'!D$14)*Assumption!$B15/1000 -> 2897617.8 | E37: =(Assumption!$C15*Assumption!$B$3*'RM Consumed_PowerSip'!E$14)*Assumption!$B15/1000 -> 3345619.2 | F37: =(Assumption!$C15*Assumption!$B$3*'RM Consumed_PowerSip'!F$14)*Assumption!$B15/1000 -> 3877104 | G37: =(Assumption!$C15*Assumption!$B$3*'RM Consumed_PowerSip'!G$14)*Assumption!$B15/1000 -> 4468602.6
A38: =Assumption!A16 -> Other Ingredients | B38: =(Assumption!$C16*Assumption!$B$3*'RM Consumed_PowerSip'!B$14)*Assumption!$B16/1000 -> 3584347.2 | C38: =(Assumption!$C16*Assumption!$B$3*'RM Consumed_PowerSip'!C$14)*Assumption!$B16/1000 -> 4183412.4 | D38: =(Assumption!$C16*Assumption!$B$3*'RM Consumed_PowerSip'!D$14)*Assumption!$B16/1000 -> 4741556.4 | E38: =(Assumption!$C16*Assumption!$B$3*'RM Consumed_PowerSip'!E$14)*Assumption!$B16/1000 -> 5474649.6 | F38: =(Assumption!$C16*Assumption!$B$3*'RM Consumed_PowerSip'!F$14)*Assumption!$B16/1000 -> 6344352 | G38: =(Assumption!$C16*Assumption!$B$3*'RM Consumed_PowerSip'!G$14)*Assumption!$B16/1000 -> 7312258.8
A39: Total | B39: =SUM(B32:B38) -> 15213563 | C39: =SUM(C32:C38) -> 17756262 | D39: =SUM(D32:D38) -> 20125273 | E39: =SUM(E32:E38) -> 23236846 | F39: =SUM(F32:F38) -> 26928250 | G39: =SUM(G32:G38) -> 31036476
A40: =Assumption!A17
A41: =Assumption!A18 -> HappyGrow
A42: =Assumption!A20 -> Water | B42: =(Assumption!$C20*Assumption!$B$4*'RM Consumed_HappyGrow'!B$14)*Assumption!$B20/1000 -> 184994.88 | C42: =(Assumption!$C20*Assumption!$B$4*'RM Consumed_HappyGrow'!C$14)*Assumption!$B20/1000 -> 206120.54 | D42: =(Assumption!$C20*Assumption!$B$4*'RM Consumed_HappyGrow'!D$14)*Assumption!$B20/1000 -> 228715.2 | E42: =(Assumption!$C20*Assumption!$B$4*'RM Consumed_HappyGrow'!E$14)*Assumption!$B20/1000 -> 254263.3 | F42: =(Assumption!$C20*Assumption!$B$4*'RM Consumed_HappyGrow'!F$14)*Assumption!$B20/1000 -> 282343.49 | G42: =(Assumption!$C20*Assumption!$B$4*'RM Consumed_HappyGrow'!G$14)*Assumption!$B20/1000 -> 312034.46
A43: =Assumption!A21 -> Oats Extract | B43: =(Assumption!$C21*Assumption!$B$4*'RM Consumed_HappyGrow'!B$14)*Assumption!$B21/1000 -> 880928 | C43: =(Assumption!$C21*Assumption!$B$4*'RM Consumed_HappyGrow'!C$14)*Assumption!$B21/1000 -> 981526.4 | D43: =(Assumption!$C21*Assumption!$B$4*'RM Consumed_HappyGrow'!D$14)*Assumption!$B21/1000 -> 1089120 | E43: =(Assumption!$C21*Assumption!$B$4*'RM Consumed_HappyGrow'!E$14)*Assumption!$B21/1000 -> 1210777.6 | F43: =(Assumption!$C21*Assumption!$B$4*'RM Consumed_HappyGrow'!F$14)*Assumption!$B21/1000 -> 1344492.8 | G43: =(Assumption!$C21*Assumption!$B$4*'RM Consumed_HappyGrow'!G$14)*Assumption!$B21/1000 -> 1485878.4
A44: =Assumption!A22 -> Ragi Extract | B44: =(Assumption!$C22*Assumption!$B$4*'RM Consumed_HappyGrow'!B$14)*Assumption!$B22/1000 -> 330348 | C44: =(Assumption!$C22*Assumption!$B$4*'RM Consumed_HappyGrow'!C$14)*Assumption!$B22/1000 -> 368072.4 | D44: =(Assumption!$C22*Assumption!$B$4*'RM Consumed_HappyGrow'!D$14)*Assumption!$B22/1000 -> 408420 | E44: =(Assumption!$C22*Assumption!$B$4*'RM Consumed_HappyGrow'!E$14)*Assumption!$B22/1000 -> 454041.6 | F44: =(Assumption!$C22*Assumption!$B$4*'RM Consumed_HappyGrow'!F$14)*Assumption!$B22/1000 -> 504184.8 | G44: =(Assumption!$C22*Assumption!$B$4*'RM Consumed_HappyGrow'!G$14)*Assumption!$B22/1000 -> 557204.4
A45: =Assumption!A23 -> Jowar Extract | B45: =(Assumption!$C23*Assumption!$B$4*'RM Consumed_HappyGrow'!B$14)*Assumption!$B23/1000 -> 111767.74 | C45: =(Assumption!$C23*Assumption!$B$4*'RM Consumed_HappyGrow'!C$14)*Assumption!$B23/1000 -> 124531.16 | D45: =(Assumption!$C23*Assumption!$B$4*'RM Consumed_HappyGrow'!D$14)*Assumption!$B23/1000 -> 138182.1 | E45: =(Assumption!$C23*Assumption!$B$4*'RM Consumed_HappyGrow'!E$14)*Assumption!$B23/1000 -> 153617.41 | F45: =(Assumption!$C23*Assumption!$B$4*'RM Consumed_HappyGrow'!F$14)*Assumption!$B23/1000 -> 170582.52 | G45: =(Assumption!$C23*Assumption!$B$4*'RM Consumed_HappyGrow'!G$14)*Assumption!$B23/1000 -> 188520.82
...

Sheet RM Consumed_PowerSip
B1: January | C1: February | D1: March | E1: April | F1: May | G1: June
A2: PowerSip
A3: Per Unit Material Consumption (in ml)
A4: =Assumption!A10 -> Water | B4: =Assumption!$B$3*Assumption!$C10 -> 105 | C4: =Assumption!$B$3*Assumption!$C10 -> 105 | D4: =Assumption!$B$3*Assumption!$C10 -> 105 | E4: =Assumption!$B$3*Assumption!$C10 -> 105 | F4: =Assumption!$B$3*Assumption!$C10 -> 105 | G4: =Assumption!$B$3*Assumption!$C10 -> 105
A5: =Assumption!A11 -> Milk | B5: =Assumption!$B$3*Assumption!$C11 -> 105 | C5: =Assumption!$B$3*Assumption!$C11 -> 105 | D5: =Assumption!$B$3*Assumption!$C11 -> 105 | E5: =Assumption!$B$3*Assumption!$C11 -> 105 | F5: =Assumption!$B$3*Assumption!$C11 -> 105 | G5: =Assumption!$B$3*Assumption!$C11 -> 105
A6: =Assumption!A12 -> Pea Protein Extract | B6: =Assumption!$B$3*Assumption!$C12 -> 30 | C6: =Assumption!$B$3*Assumption!$C12 -> 30 | D6: =Assumption!$B$3*Assumption!$C12 -> 30 | E6: =Assumption!$B$3*Assumption!$C12 -> 30 | F6: =Assumption!$B$3*Assumption!$C12 -> 30 | G6: =Assumption!$B$3*Assumption!$C12 -> 30
A7: =Assumption!A13 -> Coffee Bean Extract | B7: =Assumption!$B$3*Assumption!$C13 -> 30 | C7: =Assumption!$B$3*Assumption!$C13 -> 30 | D7: =Assumption!$B$3*Assumption!$C13 -> 30 | E7: =Assumption!$B$3*Assumption!$C13 -> 30 | F7: =Assumption!$B$3*Assumption!$C13 -> 30 | G7: =Assumption!$B$3*Assumption!$C13 -> 30
A8: =Assumption!A14 -> Dates Extract | B8: =Assumption!$B$3*Assumption!$C14 -> 15 | C8: =Assumption!$B$3*Assumption!$C14 -> 15 | D8: =Assumption!$B$3*Assumption!$C14 -> 15 | E8: =Assumption!$B$3*Assumption!$C14 -> 15 | F8: =Assumption!$B$3*Assumption!$C14 -> 15 | G8: =Assumption!$B$3*Assumption!$C14 -> 15
A9: =Assumption!A15 -> Monk Fruit Extract | B9: =Assumption!$B$3*Assumption!$C15 -> 6 | C9: =Assumption!$B$3*Assumption!$C15 -> 6 | D9: =Assumption!$B$3*Assumption!$C15 -> 6 | E9: =Assumption!$B$3*Assumption!$C15 -> 6 | F9: =Assumption!$B$3*Assumption!$C15 -> 6 | G9: =Assumption!$B$3*Assumption!$C15 -> 6
A10: =Assumption!A16 -> Other Ingredients | B10: =Assumption!$B$3*Assumption!$C16 -> 9 | C10: =Assumption!$B$3*Assumption!$C16 -> 9 | D10: =Assumption!$B$3*Assumption!$C16 -> 9 | E10: =Assumption!$B$3*Assumption!$C16 -> 9 | F10: =Assumption!$B$3*Assumption!$C16 -> 9 | G10: =Assumption!$B$3*Assumption!$C16 -> 9
A12: Sales Units
A13: Old Plan | B13: =SUMIFS('Sales Quantity'!I:I, 'Sales Quantity'!A:A, "Month1", 'Sales Quantity'!D:D, "PowerSip") / 135 -> 304436 | C13: =SUMIFS('Sales Quantity'!I:I, 'Sales Quantity'!A:A, "Month2", 'Sales Quantity'!D:D, "PowerSip") / 135 -> 334881 | D13: =SUMIFS('Sales Quantity'!I:I, 'Sales Quantity'!A:A, "Month3", 'Sales Quantity'!D:D, "PowerSip") / 135 -> 368372 | E13: =SUMIFS('Sales Quantity'!I:I, 'Sales Quantity'!A:A, "Month4", 'Sales Quantity'!D:D, "PowerSip") / 135 -> 405210 | F13: =SUMIFS('Sales Quantity'!I:I, 'Sales Quantity'!A:A, "Month5", 'Sales Quantity'!D:D, "PowerSip") / 135 -> 445733 | G13: =SUMIFS('Sales Quantity'!I:I, 'Sales Quantity'!A:A, "Month6", 'Sales Quantity'!D:D, "PowerSip") / 135 -> 490306
A14: New Plan | B14: =SUMIFS('Sales Quantity'!J:J, 'Sales Quantity'!$A:$A, "Month1", 'Sales Quantity'!$D:$D, "PowerSip") / 140 -> 331884 | C14: =SUMIFS('Sales Quantity'!J:J, 'Sales Quantity'!A:A, "Month2", 'Sales Quantity'!D:D, "PowerSip") / 140 -> 387353 | D14: =SUMIFS('Sales Quantity'!J:J, 'Sales Quantity'!A:A, "Month3", 'Sales Quantity'!D:D, "PowerSip") / 140 -> 439033 | E14: =SUMIFS('Sales Quantity'!J:J, 'Sales Quantity'!A:A, "Month4", 'Sales Quantity'!D:D, "PowerSip") / 140 -> 506912 | F14: =SUMIFS('Sales Quantity'!J:J, 'Sales Quantity'!A:A, "Month5", 'Sales Quantity'!D:D, "PowerSip") / 140 -> 587440 | G14: =SUMIFS('Sales Quantity'!J:J, 'Sales Quantity'!A:A, "Month6", 'Sales Quantity'!D:D, "PowerSip") / 140 -> 677061
A16: Raw Material
A17: Old plan
A19: =Assumption!A10 -> Water | B19: =B$13 * 300 *Assumption!$C10 / 1000 -> 31965.78 | C19: =C$13 * 300 *Assumption!$C10 / 1000 -> 35162.505 | D19: =D$13 * 300 *Assumption!$C10 / 1000 -> 38679.06 | E19: =E$13 * 300 *Assumption!$C10 / 1000 -> 42547.05 | F19: =F$13 * 300 *Assumption!$C10 / 1000 -> 46801.965 | G19: =G$13 * 300 *Assumption!$C10 / 1000 -> 51482.13
A20: =Assumption!A11 -> Milk | B20: =B$13 * 300 *Assumption!$C11 / 1000 -> 31965.78 | C20: =C$13 * 300 *Assumption!$C11 / 1000 -> 35162.505 | D20: =D$13 * 300 *Assumption!$C11 / 1000 -> 38679.06 | E20: =E$13 * 300 *Assumption!$C11 / 1000 -> 42547.05 | F20: =F$13 * 300 *Assumption!$C11 / 1000 -> 46801.965 | G20: =G$13 * 300 *Assumption!$C11 / 1000 -> 51482.13
A21: =Assumption!A12 -> Pea Protein Extract | B21: =B$13 * 300 *Assumption!$C12 / 1000 -> 9133.08 | C21: =C$13 * 300 *Assumption!$C12 / 1000 -> 10046.43 | D21: =D$13 * 300 *Assumption!$C12 / 1000 -> 11051.16 | E21: =E$13 * 300 *Assumption!$C12 / 1000 -> 12156.3 | F21: =F$13 * 300 *Assumption!$C12 / 1000 -> 13371.99 | G21: =G$13 * 300 *Assumption!$C12 / 1000 -> 14709.18
A22: =Assumption!A13 -> Coffee Bean Extract | B22: =B$13 * 300 *Assumption!$C13 / 1000 -> 9133.08 | C22: =C$13 * 300 *Assumption!$C13 / 1000 -> 10046.43 | D22: =D$13 * 300 *Assumption!$C13 / 1000 -> 11051.16 | E22: =E$13 * 300 *Assumption!$C13 / 1000 -> 12156.3 | F22: =F$13 * 300 *Assumption!$C13 / 1000 -> 13371.99 | G22: =G$13 * 300 *Assumption!$C13 / 1000 -> 14709.18
A23: =Assumption!A14 -> Dates Extract | B23: =B$13 * 300 *Assumption!$C14 / 1000 -> 4566.54 | C23: =C$13 * 300 *Assumption!$C14 / 1000 -> 5023.215 | D23: =D$13 * 300 *Assumption!$C14 / 1000 -> 5525.58 | E23: =E$13 * 300 *Assumption!$C14 / 1000 -> 6078.15 | F23: =F$13 * 300 *Assumption!$C14 / 1000 -> 6685.995 | G23: =G$13 * 300 *Assumption!$C14 / 1000 -> 7354.59
A24: =Assumption!A15 -> Monk Fruit Extract | B24: =B$13 * 300 *Assumption!$C15 / 1000 -> 1826.616 | C24: =C$13 * 300 *Assumption!$C15 / 1000 -> 2009.286 | D24: =D$13 * 300 *Assumption!$C15 / 1000 -> 2210.232 | E24: =E$13 * 300 *Assumption!$C15 / 1000 -> 2431.26 | F24: =F$13 * 300 *Assumption!$C15 / 1000 -> 2674.398 | G24: =G$13 * 300 *Assumption!$C15 / 1000 -> 2941.836
A25: =Assumption!A16 -> Other Ingredients | B25: =B$13 * 300 *Assumption!$C16 / 1000 -> 2739.924 | C25: =C$13 * 300 *Assumption!$C16 / 1000 -> 3013.929 | D25: =D$13 * 300 *Assumption!$C16 / 1000 -> 3315.348 | E25: =E$13 * 300 *Assumption!$C16 / 1000 -> 3646.89 | F25: =F$13 * 300 *Assumption!$C16 / 1000 -> 4011.597 | G25: =G$13 * 300 *Assumption!$C16 / 1000 -> 4412.754
A26: =Assumption!A17
A27: New Plan
A29: =Assumption!A10 -> Water | B29: =B$14 * 300 *Assumption!$C10 / 1000 -> 34847.82 | C29: =C$14 * 300 *Assumption!$C10 / 1000 -> 40672.065 | D29: =D$14 * 300 *Assumption!$C10 / 1000 -> 46098.465 | E29: =E$14 * 300 *Assumption!$C10 / 1000 -> 53225.76 | F29: =F$14 * 300 *Assumption!$C10 / 1000 -> 61681.2 | G29: =G$14 * 300 *Assumption!$C10 / 1000 -> 71091.405
A30: =Assumption!A11 -> Milk | B30: =B$14 * 300 *Assumption!$C11 / 1000 -> 34847.82 | C30: =C$14 * 300 *Assumption!$C11 / 1000 -> 40672.065 | D30: =D$14 * 300 *Assumption!$C11 / 1000 -> 46098.465 | E30: =E$14 * 300 *Assumption!$C11 / 1000 -> 53225.76 | F30: =F$14 * 300 *Assumption!$C11 / 1000 -> 61681.2 | G30: =G$14 * 300 *Assumption!$C11 / 1000 -> 71091.405
A31: =Assumption!A12 -> Pea Protein Extract | B31: =B$14 * 300 *Assumption!$C12 / 1000 -> 9956.52 | C31: =C$14 * 300 *Assumption!$C12 / 1000 -> 11620.59 | D31: =D$14 * 300 *Assumption!$C12 / 1000 -> 13170.99 | E31: =E$14 * 300 *Assumption!$C12 / 1000 -> 15207.36 | F31: =F$14 * 300 *Assumption!$C12 / 1000 -> 17623.2 | G31: =G$14 * 300 *Assumption!$C12 / 1000 -> 20311.83
A32: =Assumption!A13 -> Coffee Bean Extract | B32: =B$14 * 300 *Assumption!$C13 / 1000 -> 9956.52 | C32: =C$14 * 300 *Assumption!$C13 / 1000 -> 11620.59 | D32: =D$14 * 300 *Assumption!$C13 / 1000 -> 13170.99 | E32: =E$14 * 300 *Assumption!$C13 / 1000 -> 15207.36 | F32: =F$14 * 300 *Assumption!$C13 / 1000 -> 17623.2 | G32: =G$14 * 300 *Assumption!$C13 / 1000 -> 20311.83
A33: =Assumption!A14 -> Dates Extract | B33: =B$14 * 300 *Assumption!$C14 / 1000 -> 4978.26 | C33: =C$14 * 300 *Assumption!$C14 / 1000 -> 5810.295 | D33: =D$14 * 300 *Assumption!$C14 / 1000 -> 6585.495 | E33: =E$14 * 300 *Assumption!$C14 / 1000 -> 7603.68 | F33: =F$14 * 300 *Assumption!$C14 / 1000 -> 8811.6 | G33: =G$14 * 300 *Assumption!$C14 / 1000 -> 10155.915
A34: =Assumption!A15 -> Monk Fruit Extract | B34: =B$14 * 300 *Assumption!$C15 / 1000 -> 1991.304 | C34: =C$14 * 300 *Assumption!$C15 / 1000 -> 2324.118 | D34: =D$14 * 300 *Assumption!$C15 / 1000 -> 2634.198 | E34: =E$14 * 300 *Assumption!$C15 / 1000 -> 3041.472 | F34: =F$14 * 300 *Assumption!$C15 / 1000 -> 3524.64 | G34: =G$14 * 300 *Assumption!$C15 / 1000 -> 4062.366
A35: =Assumption!A16 -> Other Ingredients | B35: =B$14 * 300 *Assumption!$C16 / 1000 -> 2986.956 | C35: =C$14 * 300 *Assumption!$C16 / 1000 -> 3486.177 | D35: =D$14 * 300 *Assumption!$C16 / 1000 -> 3951.297 | E35: =E$14 * 300 *Assumption!$C16 / 1000 -> 4562.208 | F35: =F$14 * 300 *Assumption!$C16 / 1000 -> 5286.96 | G35: =G$14 * 300 *Assumption!$C16 / 1000 -> 6093.549

Sheet RM Consumed_HappyGrow
B1: January | C1: February | D1: March | E1: April | F1: May | G1: June
A2: HappyGrow
A3: Per Unit Material Consumption (in ml)
A4: =Assumption!A20 -> Water | B4: =Assumption!$B$4*Assumption!$C20 -> 84 | C4: =Assumption!$B$4*Assumption!$C20 -> 84 | D4: =Assumption!$B$4*Assumption!$C20 -> 84 | E4: =Assumption!$B$4*Assumption!$C20 -> 84 | F4: =Assumption!$B$4*Assumption!$C20 -> 84 | G4: =Assumption!$B$4*Assumption!$C20 -> 84
A5: =Assumption!A21 -> Oats Extract | B5: =Assumption!$B$4*Assumption!$C21 -> 40 | C5: =Assumption!$B$4*Assumption!$C21 -> 40 | D5: =Assumption!$B$4*Assumption!$C21 -> 40 | E5: =Assumption!$B$4*Assumption!$C21 -> 40 | F5: =Assumption!$B$4*Assumption!$C21 -> 40 | G5: =Assumption!$B$4*Assumption!$C21 -> 40
A6: =Assumption!A22 -> Ragi Extract | B6: =Assumption!$B$4*Assumption!$C22 -> 30 | C6: =Assumption!$B$4*Assumption!$C22 -> 30 | D6: =Assumption!$B$4*Assumption!$C22 -> 30 | E6: =Assumption!$B$4*Assumption!$C22 -> 30 | F6: =Assumption!$B$4*Assumption!$C22 -> 30 | G6: =Assumption!$B$4*Assumption!$C22 -> 30
A7: =Assumption!A23 -> Jowar Extract | B7: =Assumption!$B$4*Assumption!$C23 -> 14 | C7: =Assumption!$B$4*Assumption!$C23 -> 14 | D7: =Assumption!$B$4*Assumption!$C23 -> 14 | E7: =Assumption!$B$4*Assumption!$C23 -> 14 | F7: =Assumption!$B$4*Assumption!$C23 -> 14 | G7: =Assumption!$B$4*Assumption!$C23 -> 14
A8: =Assumption!A24 -> Bajra Extract | B8: =Assumption!$B$4*Assumption!$C24 -> 14 | C8: =Assumption!$B$4*Assumption!$C24 -> 14 | D8: =Assumption!$B$4*Assumption!$C24 -> 14 | E8: =Assumption!$B$4*Assumption!$C24 -> 14 | F8: =Assumption!$B$4*Assumption!$C24 -> 14 | G8: =Assumption!$B$4*Assumption!$C24 -> 14
A9: =Assumption!A25 -> Dates Extract | B9: =Assumption!$B$4*Assumption!$C25 -> 12 | C9: =Assumption!$B$4*Assumption!$C25 -> 12 | D9: =Assumption!$B$4*Assumption!$C25 -> 12 | E9: =Assumption!$B$4*Assumption!$C25 -> 12 | F9: =Assumption!$B$4*Assumption!$C25 -> 12 | G9: =Assumption!$B$4*Assumption!$C25 -> 12
A10: =Assumption!A26 -> Other Ingredients | B10: =Assumption!$B$4*Assumption!$C26 -> 6 | C10: =Assumption!$B$4*Assumption!$C26 -> 6 | D10: =Assumption!$B$4*Assumption!$C26 -> 6 | E10: =Assumption!$B$4*Assumption!$C26 -> 6 | F10: =Assumption!$B$4*Assumption!$C26 -> 6 | G10: =Assumption!$B$4*Assumption!$C26 -> 6
A12: Sales Units
A13: Old Plan | B13: =SUMIFS('Sales Quantity'!$I:$I, 'Sales Quantity'!$A:$A, "Month1", 'Sales Quantity'!$D:$D, "HappyGrow")/60 -> 269434 | C13: =SUMIFS('Sales Quantity'!$I:$I, 'Sales Quantity'!$A:$A, "Month2", 'Sales Quantity'!$D:$D, "HappyGrow")/60 -> 288294 | D13: =SUMIFS('Sales Quantity'!$I:$I, 'Sales Quantity'!$A:$A, "Month3", 'Sales Quantity'!$D:$D, "HappyGrow")/60 -> 308475 | E13: =SUMIFS('Sales Quantity'!$I:$I, 'Sales Quantity'!$A:$A, "Month4", 'Sales Quantity'!$D:$D, "HappyGrow")/60 -> 330069 | F13: =SUMIFS('Sales Quantity'!$I:$I, 'Sales Quantity'!$A:$A, "Month5", 'Sales Quantity'!$D:$D, "HappyGrow")/60 -> 353173 | G13: =SUMIFS('Sales Quantity'!$I:$I, 'Sales Quantity'!$A:$A, "Month6", 'Sales Quantity'!$D:$D, "HappyGrow")/60 -> 377898
